Workbook

Sheet Read Me
A1: Open TV Stick - pay-once business model
A3: Purpose | B3: Five-year model (2027-2031) for an open-source TV stick sold on a pay-once basis: no subscriptions, no ads on the home screen.
A4: How to use | B4: Change the blue cells on Assumptions and Products. Everything else recalculates. Yellow-filled cells are the main levers.
A6: Color key
A7: Blue text | B7: Hardcoded input you can change
A8: Black text | B8: Formula
A9: Green text | B9: Formula that pulls from another sheet
A10: Yellow fill | B10: Key lever (prices, volumes, starting cash)
A12: Sheets
A13: Assumptions | B13: Channel, staffing, fixed costs, licensing fees, other revenue streams, yearly volumes.
A14: Products | B14: Price and per-unit costs for each product, plus per-unit contribution at direct and retail.
A15: Projection | B15: Five-year volumes, revenue by stream, contribution, fixed costs, operating income, cash, and the maintenance-reserve check.
A16: Sensitivity | B16: Operating income for a chosen year across stick price and stick volume.
A17: Competitors | B17: Current competitor prices with sources, for positioning.
A19: Key simplifications
A20: Cash | B20: Cash = starting cash + cumulative operating income. Ignores inventory deposits to the ODM, payment timing, taxes, and financing. Real cash needs will be higher in growth years because inventory is paid before it sells.
A21: Other revenue | B21: FAST revenue share, referral fees, and B2B licensing are placeholders with no contracts behind them. Treated as having no direct cost.
A22: Royalties | B22: Per-unit royalties are a blended estimate (HDMI with logo, H.264, HEVC, AAC). HDMI annual fees are calculated separately and pick the cheaper tier automatically.
A23: Sensitivity | B23: The price/volume grid flexes stick contribution only. Marketing %, HDMI fees, accessories, and installed-base revenue are held at the reference year's values.
A24: Disclaimer | B24: Planning estimates, not financial, legal, or tax advice. Verify licensing terms and supplier quotes before relying on these numbers.

Sheet Assumptions
A1: Assumptions
A2: Blue = input. Single values go in column B; values that change by year go in columns C-G.
A3: Assumption | B3: Value | C3: 2027 | D3: 2028 | E3: 2029 | F3: 2030 | G3: 2031 | H3: Notes / source
A4: Sales volumes (units per year)
A5: Stick units | C5: 6000 | D5: 15000 | E5: 30000 | F5: 45000 | G5: 60000 | H5: Main product. Early years are mostly pre-orders and direct sales to enthusiasts.
A6: Pro puck units | C6: 1000 | D6: 4000 | E6: 8000 | F6: 12000 | G6: 15000 | H6: Higher-end box: more RAM, gigabit Ethernet. Competes with Shield / Google TV Streamer.
A7: DIY remote kit units | C7: 1500 | D7: 3000 | E7: 4500 | F7: 5500 | G7: 6500 | H7: Maker product; sold direct only.
A8: OTA tuner add-on units | C8: 0 | D8: 1500 | E8: 4000 | F8: 6000 | G8: 8000 | H8: Separate SKU so ATSC royalties apply only to buyers who want OTA.
A9: Accessory attach rate (% of stick + pro units) | B9: 0.2 | H9: Cases, cables, replacement and premium remotes.
A10: Codec unlock attach rate (% of stick + pro units) | B10: 0.15 | H10: Optional one-time HEVC/Dolby unlock (see Products). Set to 0% if you include codecs by default.
A12: Channel and per-unit cost rates
A13: Direct-to-consumer share of retail-eligible sales | C13: 1 | D13: 0.95 | E13: 0.85 | F13: 0.8 | G13: 0.75 | H13: Start 100% direct; add retail later. Only applies to products flagged retail-eligible on Products.
A14: Retailer margin (% of retail price) | B14: 0.3 | H14: Typical consumer-electronics retail margin is roughly 25-35%. Estimate.
A15: Payment processing (% of net revenue) | B15: 0.03 | H15: Card and platform fees. Estimate.
A16: Returns and warranty (% of net revenue) | B16: 0.04 | H16: Estimate for first-generation hardware.
A18: Installed-base revenue (placeholders: no contracts yet)
A19: Active device rate (% of all devices sold still in use) | B19: 0.85 | H19: Applied to cumulative stick + pro units.
A20: FAST revenue share ($ per active device per year) | C20: 1 | D20: 1.5 | E20: 2 | F20: 2.5 | G20: 3 | H20: Your share of ad revenue inside FAST channels you carry natively. Placeholder; depends on partner deals.
A21: Referral sign-up rate (% of active devices per year) | B21: 0.02 | H21: Users who subscribe to a paid service through the launcher. Disclosed to users.
A22: Referral bounty ($ per sign-up) | B22: 15 | H22: Placeholder; varies widely by service.
A23: B2B licensing deals (count) | C23: 0 | D23: 1 | E23: 3 | F23: 5 | G23: 8 | H23: Hotels, libraries, schools, ISPs, other hardware makers licensing the launcher/OS.
A24: Average B2B license fee ($ per deal per year) | B24: 20000 | H24: Placeholder.
A25: Community funding ($) | C25: 5000 | D25: 15000 | E25: 30000 | F25: 40000 | G25: 50000 | H25: Open Collective / sponsorships for the open-source OS.
A27: Team and operating costs
A28: Loaded cost per staff member ($ per year) | B28: 160000 | H28: Salary + benefits + payroll tax, US. Lower if hiring remotely or abroad.
A29: Software engineers (FTE) | C29: 2 | D29: 2 | E29: 3 | F29: 3 | G29: 4 | H29: Launcher, Android/BSP maintenance, security updates. This is the cost the pay-once promise must fund.
A30: Hardware / product / ODM management (FTE) | C30: 1 | D30: 1 | E30: 1 | F30: 2 | G30: 2
A31: Marketing, fixed ($) | C31: 100000 | D31: 75000 | E31: 75000 | F31: 100000 | G31: 100000 | H31: Launch campaign, reviews, community.
A32: Marketing, variable (% of total revenue) | B32: 0.06
A33: G&A: founders, legal, accounting, insurance, tools ($) | C33: 150000 | D33: 200000 | E33: 250000 | F33: 300000 | G33: 350000 | H33: Lean: founders on modest salaries early.
A35: Licensing, certification, and one-time costs
A36: HDMI low-volume tier: annual fee ($) | B36: 5000 | H36: Historically published HDMI Adopter terms (under 10,000 units/yr). Confirm with HDMI Licensing Administrator.
A37: HDMI low-volume tier: admin fee ($ per unit) | B37: 1 | H37: Charged on top of the per-unit royalty in the low-volume tier.
A38: HDMI standard tier: annual fee ($) | B38: 10000 | H38: Model picks whichever tier is cheaper each year. Per-unit royalty is in Products.
A39: Bluetooth qualification fee ($ per new design) | B39: 12000 | H39: Bluetooth SIG fee schedule effective March 2026, Adopter full qualification. bluetooth.com/fee-schedule
A40: FCC / CE / safety certification ($ per new hardware design) | B40: 20000 | H40: Estimate; using pre-certified radio modules keeps this down.
A41: New hardware designs (count) | C41: 2 | D41: 1 | E41: 1 | F41: 0 | G41: 1 | H41: 2027: stick + remote. 2028: pro puck. 2029: tuner. 2031: stick v2.
A42: New Bluetooth designs (count) | C42: 2 | D42: 1 | E42: 0 | F42: 0 | G42: 1 | H42: Designs with their own Bluetooth qualification. Tuner assumed USB-only.
A43: Tooling and ODM engineering (NRE) ($) | C43: 75000 | D43: 40000 | E43: 30000 | F43: 0 | G43: 40000 | H43: Keypad and enclosure molds, ODM customization.
A44: Legal and licensing review ($) | C44: 40000 | D44: 20000 | E44: 20000 | F44: 20000 | G44: 20000 | H44: Codec pools, content agreements, terms of service.
...

Sheet Products
A1: Products and per-unit economics
A2: Blue = input. Contribution = price after channel discount, minus processing/returns %, minus per-unit costs.
A4: Product | B4: Price | C4: Landed HW / COGS | D4: Royalties | E4: Fulfillment | F4: Support | G4: Retail eligible (1/0) | H4: Variable cost / unit | I4: Contribution / unit (direct) | J4: Margin % (direct) | K4: Contribution / unit (retail) | L4: Notes
A5: Stick + remote + power dongle | B5: 89 | C5: 42 | D5: 2 | E5: 7 | F5: 1.5 | G5: 1 | H5: =SUM(C5:F5) -> 52.5 | I5: =B5*(1-Assumptions!$B$15-Assumptions!$B$16)-H5 -> 30.27 | J5: =IF(B5=0,0,I5/B5) -> 0.34011236 | K5: =IF(G5=1,B5*(1-Assumptions!$B$14)*(1-Assumptions!$B$15-Assumptions!$B$16)-H5,"direct only") -> 5.439 | L5: Landed ODM cost estimate. A comparable RK3539 4GB/32GB stick retails for $44.96 on AliExpress (cnx-software.com, Jun 2026), so factory cost is lower.
A6: Pro puck | B6: 119 | C6: 62 | D6: 2.25 | E6: 8 | F6: 2 | G6: 1 | H6: =SUM(C6:F6) -> 74.25 | I6: =B6*(1-Assumptions!$B$15-Assumptions!$B$16)-H6 -> 36.42 | J6: =IF(B6=0,0,I6/B6) -> 0.30605042 | K6: =IF(G6=1,B6*(1-Assumptions!$B$14)*(1-Assumptions!$B$15-Assumptions!$B$16)-H6,"direct only") -> 3.219 | L6: More RAM/storage, gigabit Ethernet. Estimate.
A7: DIY remote kit | B7: 29 | C7: 9 | D7: 0 | E7: 5 | F7: 1 | G7: 0 | H7: =SUM(C7:F7) -> 15 | I7: =B7*(1-Assumptions!$B$15-Assumptions!$B$16)-H7 -> 11.97 | J7: =IF(B7=0,0,I7/B7) -> 0.41275862 | K7: =IF(G7=1,B7*(1-Assumptions!$B$14)*(1-Assumptions!$B$15-Assumptions!$B$16)-H7,"direct only") -> direct only | L7: Sold direct only. Bluetooth qualification counted in fixed costs.
A8: OTA tuner add-on | B8: 49 | C8: 22 | D8: 1 | E8: 6 | F8: 2 | G8: 1 | H8: =SUM(C8:F8) -> 31 | I8: =B8*(1-Assumptions!$B$15-Assumptions!$B$16)-H8 -> 14.57 | J8: =IF(B8=0,0,I8/B8) -> 0.29734694 | K8: =IF(G8=1,B8*(1-Assumptions!$B$14)*(1-Assumptions!$B$15-Assumptions!$B$16)-H8,"direct only") -> 0.899 | L8: Avanci Broadcast has waived ATSC 3.0 fees on the first 75,000 units for new dongle makers who sign early; royalty here is a placeholder.
A9: Accessories (average) | B9: 19 | C9: 6 | D9: 0 | E9: 3 | F9: 0.5 | G9: 0 | H9: =SUM(C9:F9) -> 9.5 | I9: =B9*(1-Assumptions!$B$15-Assumptions!$B$16)-H9 -> 8.17 | J9: =IF(B9=0,0,I9/B9) -> 0.43 | K9: =IF(G9=1,B9*(1-Assumptions!$B$14)*(1-Assumptions!$B$15-Assumptions!$B$16)-H9,"direct only") -> direct only | L9: Volume = attach rate x devices sold (Assumptions).
A10: Codec unlock (digital) | B10: 4.99 | C10: 0 | D10: 1.5 | E10: 0 | F10: 0.1 | G10: 0 | H10: =SUM(C10:F10) -> 1.6 | I10: =B10*(1-Assumptions!$B$15-Assumptions!$B$16)-H10 -> 3.0407 | J10: =IF(B10=0,0,I10/B10) -> 0.60935872 | K10: =IF(G10=1,B10*(1-Assumptions!$B$14)*(1-Assumptions!$B$15-Assumptions!$B$16)-H10,"direct only") -> direct only | L10: Volume = attach rate x devices sold. Royalty passed through to pools.
A12: Royalty blend for stick: HDMI ~$0.05 with logo, H.264, HEVC (low-price-device discount), AAC. Rough estimate; see licensing discussion.

Sheet Projection
A1: Five-year projection
A2: All formulas. Change inputs on Assumptions and Products.
A3: Line item | C3: 2027 | D3: 2028 | E3: 2029 | F3: 2030 | G3: 2031
A4: Volumes
A5: Stick units | C5: =Assumptions!C$5 -> 6000 | D5: =Assumptions!D$5 -> 15000 | E5: =Assumptions!E$5 -> 30000 | F5: =Assumptions!F$5 -> 45000 | G5: =Assumptions!G$5 -> 60000
A6: Pro puck units | C6: =Assumptions!C$6 -> 1000 | D6: =Assumptions!D$6 -> 4000 | E6: =Assumptions!E$6 -> 8000 | F6: =Assumptions!F$6 -> 12000 | G6: =Assumptions!G$6 -> 15000
A7: DIY remote kit units | C7: =Assumptions!C$7 -> 1500 | D7: =Assumptions!D$7 -> 3000 | E7: =Assumptions!E$7 -> 4500 | F7: =Assumptions!F$7 -> 5500 | G7: =Assumptions!G$7 -> 6500
A8: OTA tuner units | C8: =Assumptions!C$8 -> 0 | D8: =Assumptions!D$8 -> 1500 | E8: =Assumptions!E$8 -> 4000 | F8: =Assumptions!F$8 -> 6000 | G8: =Assumptions!G$8 -> 8000
A9: Devices sold (stick + pro) | C9: =C5+C6 -> 7000 | D9: =D5+D6 -> 19000 | E9: =E5+E6 -> 38000 | F9: =F5+F6 -> 57000 | G9: =G5+G6 -> 75000
A10: Accessory units | C10: =C9*Assumptions!$B$9 -> 1400 | D10: =D9*Assumptions!$B$9 -> 3800 | E10: =E9*Assumptions!$B$9 -> 7600 | F10: =F9*Assumptions!$B$9 -> 11400 | G10: =G9*Assumptions!$B$9 -> 15000
A11: Codec unlocks | C11: =C9*Assumptions!$B$10 -> 1050 | D11: =D9*Assumptions!$B$10 -> 2850 | E11: =E9*Assumptions!$B$10 -> 5700 | F11: =F9*Assumptions!$B$10 -> 8550 | G11: =G9*Assumptions!$B$10 -> 11250
A12: Cumulative devices sold | C12: =C9 -> 7000 | D12: =C12+D9 -> 26000 | E12: =D12+E9 -> 64000 | F12: =E12+F9 -> 121000 | G12: =F12+G9 -> 196000
A13: Active installed base (end of year) | C13: =C12*Assumptions!$B$19 -> 5950 | D13: =D12*Assumptions!$B$19 -> 22100 | E13: =E12*Assumptions!$B$19 -> 54400 | F13: =F12*Assumptions!$B$19 -> 102850 | G13: =G12*Assumptions!$B$19 -> 166600
A14: Active installed base (average) | C14: =C13/2 -> 2975 | D14: =(C13+D13)/2 -> 14025 | E14: =(D13+E13)/2 -> 38250 | F14: =(E13+F13)/2 -> 78625 | G14: =(F13+G13)/2 -> 134725
A16: Hardware and product economics
A17: Stick + remote + power dongle
A18: Gross revenue | C18: =C5*Products!$B$5 -> 534000 | D18: =D5*Products!$B$5 -> 1335000 | E18: =E5*Products!$B$5 -> 2670000 | F18: =F5*Products!$B$5 -> 4005000 | G18: =G5*Products!$B$5 -> 5340000
A19: Retailer margin | C19: =-C18*Products!$G$5*(1-Assumptions!C$13)*Assumptions!$B$14 -> 0 | D19: =-D18*Products!$G$5*(1-Assumptions!D$13)*Assumptions!$B$14 -> -20025 | E19: =-E18*Products!$G$5*(1-Assumptions!E$13)*Assumptions!$B$14 -> -120150 | F19: =-F18*Products!$G$5*(1-Assumptions!F$13)*Assumptions!$B$14 -> -240300 | G19: =-G18*Products!$G$5*(1-Assumptions!G$13)*Assumptions!$B$14 -> -400500
A20: Net revenue | C20: =C18+C19 -> 534000 | D20: =D18+D19 -> 1314975 | E20: =E18+E19 -> 2549850 | F20: =F18+F19 -> 3764700 | G20: =G18+G19 -> 4939500
A21: Processing and returns | C21: =-C20*(Assumptions!$B$15+Assumptions!$B$16) -> -37380 | D21: =-D20*(Assumptions!$B$15+Assumptions!$B$16) -> -92048.25 | E21: =-E20*(Assumptions!$B$15+Assumptions!$B$16) -> -178489.5 | F21: =-F20*(Assumptions!$B$15+Assumptions!$B$16) -> -263529 | G21: =-G20*(Assumptions!$B$15+Assumptions!$B$16) -> -345765
A22: Variable costs (COGS, royalties, fulfillment, support) | C22: =-C5*Products!$H$5 -> -315000 | D22: =-D5*Products!$H$5 -> -787500 | E22: =-E5*Products!$H$5 -> -1575000 | F22: =-F5*Products!$H$5 -> -2362500 | G22: =-G5*Products!$H$5 -> -3150000
A23: Contribution | C23: =C20+C21+C22 -> 181620 | D23: =D20+D21+D22 -> 435426.75 | E23: =E20+E21+E22 -> 796360.5 | F23: =F20+F21+F22 -> 1138671 | G23: =G20+G21+G22 -> 1443735
A24: Pro puck
A25: Gross revenue | C25: =C6*Products!$B$6 -> 119000 | D25: =D6*Products!$B$6 -> 476000 | E25: =E6*Products!$B$6 -> 952000 | F25: =F6*Products!$B$6 -> 1428000 | G25: =G6*Products!$B$6 -> 1785000
A26: Retailer margin | C26: =-C25*Products!$G$6*(1-Assumptions!C$13)*Assumptions!$B$14 -> 0 | D26: =-D25*Products!$G$6*(1-Assumptions!D$13)*Assumptions!$B$14 -> -7140 | E26: =-E25*Products!$G$6*(1-Assumptions!E$13)*Assumptions!$B$14 -> -42840 | F26: =-F25*Products!$G$6*(1-Assumptions!F$13)*Assumptions!$B$14 -> -85680 | G26: =-G25*Products!$G$6*(1-Assumptions!G$13)*Assumptions!$B$14 -> -133875
A27: Net revenue | C27: =C25+C26 -> 119000 | D27: =D25+D26 -> 468860 | E27: =E25+E26 -> 909160 | F27: =F25+F26 -> 1342320 | G27: =G25+G26 -> 1651125
A28: Processing and returns | C28: =-C27*(Assumptions!$B$15+Assumptions!$B$16) -> -8330 | D28: =-D27*(Assumptions!$B$15+Assumptions!$B$16) -> -32820.2 | E28: =-E27*(Assumptions!$B$15+Assumptions!$B$16) -> -63641.2 | F28: =-F27*(Assumptions!$B$15+Assumptions!$B$16) -> -93962.4 | G28: =-G27*(Assumptions!$B$15+Assumptions!$B$16) -> -115578.75
A29: Variable costs (COGS, royalties, fulfillment, support) | C29: =-C6*Products!$H$6 -> -74250 | D29: =-D6*Products!$H$6 -> -297000 | E29: =-E6*Products!$H$6 -> -594000 | F29: =-F6*Products!$H$6 -> -891000 | G29: =-G6*Products!$H$6 -> -1113750
A30: Contribution | C30: =C27+C28+C29 -> 36420 | D30: =D27+D28+D29 -> 139039.8 | E30: =E27+E28+E29 -> 251518.8 | F30: =F27+F28+F29 -> 357357.6 | G30: =G27+G28+G29 -> 421796.25
A31: DIY remote kit
A32: Gross revenue | C32: =C7*Products!$B$7 -> 43500 | D32: =D7*Products!$B$7 -> 87000 | E32: =E7*Products!$B$7 -> 130500 | F32: =F7*Products!$B$7 -> 159500 | G32: =G7*Products!$B$7 -> 188500
A33: Retailer margin | C33: =-C32*Products!$G$7*(1-Assumptions!C$13)*Assumptions!$B$14 -> 0 | D33: =-D32*Products!$G$7*(1-Assumptions!D$13)*Assumptions!$B$14 -> 0 | E33: =-E32*Products!$G$7*(1-Assumptions!E$13)*Assumptions!$B$14 -> 0 | F33: =-F32*Products!$G$7*(1-Assumptions!F$13)*Assumptions!$B$14 -> 0 | G33: =-G32*Products!$G$7*(1-Assumptions!G$13)*Assumptions!$B$14 -> 0
A34: Net revenue | C34: =C32+C33 -> 43500 | D34: =D32+D33 -> 87000 | E34: =E32+E33 -> 130500 | F34: =F32+F33 -> 159500 | G34: =G32+G33 -> 188500
A35: Processing and returns | C35: =-C34*(Assumptions!$B$15+Assumptions!$B$16) -> -3045 | D35: =-D34*(Assumptions!$B$15+Assumptions!$B$16) -> -6090 | E35: =-E34*(Assumptions!$B$15+Assumptions!$B$16) -> -9135 | F35: =-F34*(Assumptions!$B$15+Assumptions!$B$16) -> -11165 | G35: =-G34*(Assumptions!$B$15+Assumptions!$B$16) -> -13195
A36: Variable costs (COGS, royalties, fulfillment, support) | C36: =-C7*Products!$H$7 -> -22500 | D36: =-D7*Products!$H$7 -> -45000 | E36: =-E7*Products!$H$7 -> -67500 | F36: =-F7*Products!$H$7 -> -82500 | G36: =-G7*Products!$H$7 -> -97500
A37: Contribution | C37: =C34+C35+C36 -> 17955 | D37: =D34+D35+D36 -> 35910 | E37: =E34+E35+E36 -> 53865 | F37: =F34+F35+F36 -> 65835 | G37: =G34+G35+G36 -> 77805
A38: OTA tuner add-on
A39: Gross revenue | C39: =C8*Products!$B$8 -> 0 | D39: =D8*Products!$B$8 -> 73500 | E39: =E8*Products!$B$8 -> 196000 | F39: =F8*Products!$B$8 -> 294000 | G39: =G8*Products!$B$8 -> 392000
A40: Retailer margin | C40: =-C39*Products!$G$8*(1-Assumptions!C$13)*Assumptions!$B$14 -> 0 | D40: =-D39*Products!$G$8*(1-Assumptions!D$13)*Assumptions!$B$14 -> -1102.5 | E40: =-E39*Products!$G$8*(1-Assumptions!E$13)*Assumptions!$B$14 -> -8820 | F40: =-F39*Products!$G$8*(1-Assumptions!F$13)*Assumptions!$B$14 -> -17640 | G40: =-G39*Products!$G$8*(1-Assumptions!G$13)*Assumptions!$B$14 -> -29400
A41: Net revenue | C41: =C39+C40 -> 0 | D41: =D39+D40 -> 72397.5 | E41: =E39+E40 -> 187180 | F41: =F39+F40 -> 276360 | G41: =G39+G40 -> 362600
...

Sheet Sensitivity
A1: Sensitivity: stick price vs stick volume
A2: Operating income for the reference year if only stick price and stick units change. Everything else stays as planned for that year.
A4: Reference year | B4: 2029 | C4: Type one of 2027-2031
A5: Year index | B5: =MATCH(B4,Projection!$C$3:$G$3,0) -> 3
A6: Operating income excluding stick contribution | B6: =INDEX(Projection!$C$84:$G$84,B5)-INDEX(Projection!$C$23:$G$23,B5) -> -679790.29
A7: Direct share that year | B7: =INDEX(Assumptions!$C$13:$G$13,B5) -> 0.85
A8: Stick variable cost per unit | B8: =Products!$H$5 -> 52.5
A10: Stick price ↓ / stick units → | B10: 5000 | C10: 10000 | D10: 20000 | E10: 40000 | F10: 60000
A11: 69 | B11: =$B$6+($A11*(1-Products!$G$5*(1-$B$7)*Assumptions!$B$14)*(1-Assumptions!$B$15-Assumptions!$B$16)-$B$8)*B$10 -> -635878.54 | C11: =$B$6+($A11*(1-Products!$G$5*(1-$B$7)*Assumptions!$B$14)*(1-Assumptions!$B$15-Assumptions!$B$16)-$B$8)*C$10 -> -591966.79 | D11: =$B$6+($A11*(1-Products!$G$5*(1-$B$7)*Assumptions!$B$14)*(1-Assumptions!$B$15-Assumptions!$B$16)-$B$8)*D$10 -> -504143.29 | E11: =$B$6+($A11*(1-Products!$G$5*(1-$B$7)*Assumptions!$B$14)*(1-Assumptions!$B$15-Assumptions!$B$16)-$B$8)*E$10 -> -328496.29 | F11: =$B$6+($A11*(1-Products!$G$5*(1-$B$7)*Assumptions!$B$14)*(1-Assumptions!$B$15-Assumptions!$B$16)-$B$8)*F$10 -> -152849.29
A12: 79 | B12: =$B$6+($A12*(1-Products!$G$5*(1-$B$7)*Assumptions!$B$14)*(1-Assumptions!$B$15-Assumptions!$B$16)-$B$8)*B$10 -> -591471.04 | C12: =$B$6+($A12*(1-Products!$G$5*(1-$B$7)*Assumptions!$B$14)*(1-Assumptions!$B$15-Assumptions!$B$16)-$B$8)*C$10 -> -503151.79 | D12: =$B$6+($A12*(1-Products!$G$5*(1-$B$7)*Assumptions!$B$14)*(1-Assumptions!$B$15-Assumptions!$B$16)-$B$8)*D$10 -> -326513.29 | E12: =$B$6+($A12*(1-Products!$G$5*(1-$B$7)*Assumptions!$B$14)*(1-Assumptions!$B$15-Assumptions!$B$16)-$B$8)*E$10 -> 26763.71 | F12: =$B$6+($A12*(1-Products!$G$5*(1-$B$7)*Assumptions!$B$14)*(1-Assumptions!$B$15-Assumptions!$B$16)-$B$8)*F$10 -> 380040.71
A13: 89 | B13: =$B$6+($A13*(1-Products!$G$5*(1-$B$7)*Assumptions!$B$14)*(1-Assumptions!$B$15-Assumptions!$B$16)-$B$8)*B$10 -> -547063.54 | C13: =$B$6+($A13*(1-Products!$G$5*(1-$B$7)*Assumptions!$B$14)*(1-Assumptions!$B$15-Assumptions!$B$16)-$B$8)*C$10 -> -414336.79 | D13: =$B$6+($A13*(1-Products!$G$5*(1-$B$7)*Assumptions!$B$14)*(1-Assumptions!$B$15-Assumptions!$B$16)-$B$8)*D$10 -> -148883.29 | E13: =$B$6+($A13*(1-Products!$G$5*(1-$B$7)*Assumptions!$B$14)*(1-Assumptions!$B$15-Assumptions!$B$16)-$B$8)*E$10 -> 382023.71 | F13: =$B$6+($A13*(1-Products!$G$5*(1-$B$7)*Assumptions!$B$14)*(1-Assumptions!$B$15-Assumptions!$B$16)-$B$8)*F$10 -> 912930.71
A14: 99 | B14: =$B$6+($A14*(1-Products!$G$5*(1-$B$7)*Assumptions!$B$14)*(1-Assumptions!$B$15-Assumptions!$B$16)-$B$8)*B$10 -> -502656.04 | C14: =$B$6+($A14*(1-Products!$G$5*(1-$B$7)*Assumptions!$B$14)*(1-Assumptions!$B$15-Assumptions!$B$16)-$B$8)*C$10 -> -325521.79 | D14: =$B$6+($A14*(1-Products!$G$5*(1-$B$7)*Assumptions!$B$14)*(1-Assumptions!$B$15-Assumptions!$B$16)-$B$8)*D$10 -> 28746.71 | E14: =$B$6+($A14*(1-Products!$G$5*(1-$B$7)*Assumptions!$B$14)*(1-Assumptions!$B$15-Assumptions!$B$16)-$B$8)*E$10 -> 737283.71 | F14: =$B$6+($A14*(1-Products!$G$5*(1-$B$7)*Assumptions!$B$14)*(1-Assumptions!$B$15-Assumptions!$B$16)-$B$8)*F$10 -> 1445820.7
A15: 109 | B15: =$B$6+($A15*(1-Products!$G$5*(1-$B$7)*Assumptions!$B$14)*(1-Assumptions!$B$15-Assumptions!$B$16)-$B$8)*B$10 -> -458248.54 | C15: =$B$6+($A15*(1-Products!$G$5*(1-$B$7)*Assumptions!$B$14)*(1-Assumptions!$B$15-Assumptions!$B$16)-$B$8)*C$10 -> -236706.79 | D15: =$B$6+($A15*(1-Products!$G$5*(1-$B$7)*Assumptions!$B$14)*(1-Assumptions!$B$15-Assumptions!$B$16)-$B$8)*D$10 -> 206376.71 | E15: =$B$6+($A15*(1-Products!$G$5*(1-$B$7)*Assumptions!$B$14)*(1-Assumptions!$B$15-Assumptions!$B$16)-$B$8)*E$10 -> 1092543.7 | F15: =$B$6+($A15*(1-Products!$G$5*(1-$B$7)*Assumptions!$B$14)*(1-Assumptions!$B$15-Assumptions!$B$16)-$B$8)*F$10 -> 1978710.7
A17: Edit the blue price and unit values to test other points. Red = loss, green = profit.

Sheet Competitors
A1: Competitor pricing (US, checked October 2026)
A2: List prices after the mid-2026 industry-wide increases. Sale prices are frequent and deep, especially from Amazon.
A4: Device | B4: List price | C4: Recent sale price | D4: Notes | E4: Source
A5: Amazon Fire TV Stick HD | B5: 39.99 | C5: 17.99 | D5: List price after Aug 2026 increase; sale via coupon. | E5: slickdeals.net, Aug 23 2026
A6: Amazon Fire TV Stick 4K Select | B6: 49.99 | C6: 17 | D6: Runs Vega OS; only Amazon Appstore apps (no sideloading). | E6: slickdeals.net Aug 2026; newsbytesapp.com Prime Day 2026
A7: Amazon Fire TV Stick 4K (2026) | B7: 59.99 | C7: 29.99 | D7: Sale during Prime Big Deal Days, Oct 2026. | E7: americantv.com, Oct 6 2026
A8: Amazon Fire TV Stick 4K Plus | B8: 69.99 | C8: 24.99 | D8: Sale via coupon. | E8: slickdeals.net, Aug 23 2026
A9: Amazon Fire TV Stick 4K Max | B9: 84.99 | C9: n/a | D9: Raised from $59.99. | E9: digitaltrends.com, 2026
A10: Roku Streaming Stick | B10: 40 | C10: 19.99 | D10: Raised from $30 (Jul 2026). | E10: Ars Technica, Jul 24 2026; americantv.com Oct 2026
A11: Roku Streaming Stick Plus | B11: 60 | C11: 34 | D11: Raised from $40. | E11: Ars Technica, Jul 24 2026; americantv.com Oct 2026
A12: Roku Streaming Stick 4K | B12: 80 | C12: n/a | D12: Raised from $50. | E12: Ars Technica, Jul 24 2026
A13: Roku Ultra | B13: 150 | C13: n/a | D13: Raised from $100. | E13: Ars Technica, Jul 24 2026
A14: Walmart Onn 4K Plus | B14: 49.98 | C14: n/a | D14: Raised twice from $29.88. | E14: aftvnews.com, 2026
A15: Walmart Onn 4K Pro (2026) | B15: 60 | C15: n/a | D15: Strongest value Google TV box. | E15: androidauthority.com, Sep 1 2026
A16: Google TV Streamer | B16: 149.99 | C16: n/a | D16: Raised from $99.99 on Aug 31 2026, citing component costs. | E16: androidauthority.com, Sep 1 2026
A17: Apple TV 4K (Wi-Fi) | B17: 199 | C17: n/a | D17: Raised from $129; Ethernet model $249. | E17: digitaltrends.com, 2026
A18: Nvidia Shield TV Pro | B18: 199 | C18: n/a | D18: Enthusiast / home-media favorite. | E18: newsbytesapp.com, Prime Day 2026
A19: RK3539 stick, 4GB/32GB (generic) | B19: 44.96 | C19: n/a | D19: ODM reference point, AliExpress; not a retail competitor in the US. | E19: cnx-software.com, Jun 18 2026
A21: Your stick (from Products) | B21: =Products!$B$5 -> 89
A22: Your pro puck (from Products) | B22: =Products!$B$6 -> 119
